Workbook

Sheet Вывод
A1: Суть теста: | B1: Новая форма оплаты с автозаполнением (Группа B) против старой (Группа A)
A2: Результат: | B2: Группа A (старая): 65,5% (491 из 750)
B3: Группа B (новая): 80,4% (603 из 750)
A4: Рост: | B4: ~22,8% ,+14,9 п.п.
A5: Обоснование: | B5: Z-тест =6,51 , p-value=<0,0000000001 .p=<0,05 Разница статистически значима
A6: A/B тест: | B6: Парадокс Симпсона нет.Группа B выигрывает и на Android (79,9% против 64,3%), и на iOS (80,8% против 66,9%)
A7: Рекомендация: | B7: Рекомендую раскатывать на 100% и отслеживать показатели ,новая форма работает лучше везде.

Sheet Расчеты
A1: step4_success | B1: (несколько элементов) | F1: Воронка | G1: android | H1: ios
F2: Группа ''A'' | G2: =B23/B20 -> 0.64285714 | H2: =C23/C20 -> 0.66860465
A3: Число разных элементов в столбце user_id | B3: Названия столбцов | F3: Группа ''B'' | G3: =B24/B21 -> 0.79945799 | H3: =C24/C21 -> 0.80839895
A4: Названия строк | B4: android | C4: ios | D4: Общий итог
A5: A | B5: 261 | C5: 230 | D5: 491 | F5: Воронка | G5: шаг 1 | H5: шаг 4
A6: B | B6: 295 | C6: 308 | D6: 603 | F6: Группа ''A'' | G6: 750 | H6: 491
A7: Общий итог | B7: 556 | C7: 538 | D7: 1094 | F7: Группа ''B'' | G7: 750 | H7: 603
D8: Проверка: конверсия как сумма по устройствам
A9: Названия строк | B9: Число разных элементов в столбце user_id | D9: Воронка (android+iOS)проверка
A10: Москва | B10: 594 | D10: Группа ''A'' (старая форма) | E10: =(B23+C23)/(B20+C20) -> 0.65466667
A11: Регион | B11: 513 | D11: Группа ''B'' (новая форма) | E11: =(B24+C24)/(B21+C21) -> 0.804
A12: СПб | B12: 393
A13: Общий итог | B13: 1500 | D13: Δ, п.п | E13: =(E11-E10)*100 -> 14.933333
A14: Воронка | D14: Рост на | E14: =(E17-E16)/E16 -> 0.22810591
A15: Группа | B15: 1. Открыл форму | C15: 2. Ввёл реквизиты | D15: 3. Подтвердил платёж | E15: 4. Успешная оплата
A16: Группа ''A'' (старая форма) | B16: 750 | C16: 670 | D16: 546 | E16: 491
A17: Группа ''B'' (новая форма) | B17: 750 | C17: 707 | D17: 644 | E17: 603
A18: Конверсия по устройствам: исходные числа, людей | E18: Общая конверсия: шаг 1 → шаг 4 (успешная оплата), % (по людям)
A19: Открыли форму (шаг 1) по устройствам, людей | B19: android | C19: ios | E19: Группа | F19: Открыли форму | G19: Успешная оплата | H19: Конверсия
A20: Группа ''A'' (старая форма) | B20: 406 | C20: 344 | E20: A (старая форма) | F20: 750 | G20: 491 | H20: 0.655
A21: Группа ''B'' (новая форма) | B21: 369 | C21: 381 | E21: B (новая форма) | F21: 750 | G21: 603 | H21: 0.804
A22: Успешная оплата (шаг 4) по устройствам, людей | B22: android | C22: ios
A23: Группа ''A'' (старая форма) | B23: 261 | C23: 230
A24: Группа ''B'' (новая форма) | B24: 295 | C24: 308
A25: Конверсия по шагам воронки, %
A26: Переход | B26: Группа "A" | C26: Группа "B" | D26: Разница
A27: Открыл форму → ввёл реквизиты | B27: 0.893 | C27: 0.943 | D27: +4,9 п.п.
A28: Ввёл реквизиты → подтвердил платёж | B28: 0.815 | C28: 0.911 | D28: +9,6 п.п.
A29: Подтвердил платёж → успешная оплата | B29: 0.899 | C29: 0.936 | D29: +3,7 п.п.

Sheet Пользователи чистые
A1: user_id | B1: group | C1: age | D1: city | E1: device_type | F1: Ошибки
A2: 1001 | B2: A | C2: 31 | D2: Москва | E2: ios | F2: =IF(OR(C2<18,C2>80),"выброс","ок") -> ок
A3: 1002 | B3: A | C3: 31 | D3: Москва | E3: ios | F3: =IF(OR(C3<18,C3>80),"выброс","ок") -> ок
A4: 1003 | B4: A | C4: 25 | D4: Москва | E4: android | F4: =IF(OR(C4<18,C4>80),"выброс","ок") -> ок
A5: 1004 | B5: A | C5: 20 | D5: Москва | E5: ios | F5: =IF(OR(C5<18,C5>80),"выброс","ок") -> ок
A6: 1005 | B6: A | C6: 34 | D6: Москва | E6: ios | F6: =IF(OR(C6<18,C6>80),"выброс","ок") -> ок
A7: 1006 | B7: A | C7: 42 | D7: Регион | E7: android | F7: =IF(OR(C7<18,C7>80),"выброс","ок") -> ок
A8: 1007 | B8: A | C8: 34 | D8: Регион | E8: ios | F8: =IF(OR(C8<18,C8>80),"выброс","ок") -> ок
A9: 1008 | B9: A | C9: 43 | D9: Регион | E9: ios | F9: =IF(OR(C9<18,C9>80),"выброс","ок") -> ок
A10: 1009 | B10: A | C10: 30 | D10: Москва | E10: android | F10: =IF(OR(C10<18,C10>80),"выброс","ок") -> ок
A11: 1010 | B11: A | C11: 26 | D11: Москва | E11: android | F11: =IF(OR(C11<18,C11>80),"выброс","ок") -> ок
A12: 1011 | B12: A | C12: 45 | D12: СПб | E12: ios | F12: =IF(OR(C12<18,C12>80),"выброс","ок") -> ок
A13: 1012 | B13: A | C13: 41 | D13: Регион | E13: ios | F13: =IF(OR(C13<18,C13>80),"выброс","ок") -> ок
... A1501: 2500 | B1501: B | C1501: 39 | D1501: Москва | E1501: ios | F1501: =IF(OR(C1501<18,C1501>80),"выброс","ок") -> ок

Sheet Платежи чистые
A1: payment_id | B1: user_id | C1: group | D1: step1_opened | E1: step2_entered | F1: step3_confirmed | G1: step4_success | H1: Группа (проверка) | I1: Ошибки
A2: 5001 | B2: 1001 | C2: A | D2: 45398.254 | E2: 45398.257 | H2: =IFERROR(VLOOKUP(B2,Пользователи!$A:$B,2,0),"нет в списке") -> A | I2: =IF(H2="нет в списке","нет пользователя",IF(H2<>C2,"группа не совпала","ок")) -> ок
A3: 5002 | B3: 1002 | C3: A | D3: 45394.318 | E3: 45394.32 | H3: =IFERROR(VLOOKUP(B3,Пользователи!$A:$B,2,0),"нет в списке") -> A | I3: =IF(H3="нет в списке","нет пользователя",IF(H3<>C3,"группа не совпала","ок")) -> ок
A4: 5003 | B4: 1003 | C4: A | D4: 45408.835 | E4: 45408.838 | H4: =IFERROR(VLOOKUP(B4,Пользователи!$A:$B,2,0),"нет в списке") -> A | I4: =IF(H4="нет в списке","нет пользователя",IF(H4<>C4,"группа не совпала","ок")) -> ок
A5: 5004 | B5: 1004 | C5: A | D5: 45391.668 | H5: =IFERROR(VLOOKUP(B5,Пользователи!$A:$B,2,0),"нет в списке") -> A | I5: =IF(H5="нет в списке","нет пользователя",IF(H5<>C5,"группа не совпала","ок")) -> ок
A6: 5005 | B6: 1004 | C6: A | D6: 45386.157 | E6: 45386.162 | F6: 45386.165 | G6: 45386.168 | H6: =IFERROR(VLOOKUP(B6,Пользователи!$A:$B,2,0),"нет в списке") -> A | I6: =IF(H6="нет в списке","нет пользователя",IF(H6<>C6,"группа не совпала","ок")) -> ок
A7: 5006 | B7: 1004 | C7: A | D7: 45406.726 | E7: 45406.727 | F7: 45406.729 | G7: 45406.733 | H7: =IFERROR(VLOOKUP(B7,Пользователи!$A:$B,2,0),"нет в списке") -> A | I7: =IF(H7="нет в списке","нет пользователя",IF(H7<>C7,"группа не совпала","ок")) -> ок
A8: 5007 | B8: 1005 | C8: A | D8: 45393.882 | E8: 45393.883 | H8: =IFERROR(VLOOKUP(B8,Пользователи!$A:$B,2,0),"нет в списке") -> A | I8: =IF(H8="нет в списке","нет пользователя",IF(H8<>C8,"группа не совпала","ок")) -> ок
A9: 5008 | B9: 1006 | C9: A | D9: 45394.575 | E9: 45394.578 | F9: 45394.58 | G9: 45394.583 | H9: =IFERROR(VLOOKUP(B9,Пользователи!$A:$B,2,0),"нет в списке") -> A | I9: =IF(H9="нет в списке","нет пользователя",IF(H9<>C9,"группа не совпала","ок")) -> ок
A10: 5009 | B10: 1007 | C10: A | D10: 45391.478 | E10: 45391.479 | F10: 45391.483 | G10: 45391.488 | H10: =IFERROR(VLOOKUP(B10,Пользователи!$A:$B,2,0),"нет в списке") -> A | I10: =IF(H10="нет в списке","нет пользователя",IF(H10<>C10,"группа не совпала","ок")) -> ок
A11: 5010 | B11: 1007 | C11: A | D11: 45390.287 | H11: =IFERROR(VLOOKUP(B11,Пользователи!$A:$B,2,0),"нет в списке") -> A | I11: =IF(H11="нет в списке","нет пользователя",IF(H11<>C11,"группа не совпала","ок")) -> ок
A12: 5011 | B12: 1007 | C12: A | D12: 45405.374 | E12: 45405.374 | F12: 45405.376 | H12: =IFERROR(VLOOKUP(B12,Пользователи!$A:$B,2,0),"нет в списке") -> A | I12: =IF(H12="нет в списке","нет пользователя",IF(H12<>C12,"группа не совпала","ок")) -> ок
A13: 5012 | B13: 1008 | C13: A | D13: 45391.378 | H13: =IFERROR(VLOOKUP(B13,Пользователи!$A:$B,2,0),"нет в списке") -> A | I13: =IF(H13="нет в списке","нет пользователя",IF(H13<>C13,"группа не совпала","ок")) -> ок
A14: 5013 | B14: 1009 | C14: A | D14: 45406.451 | E14: 45406.454 | H14: =IFERROR(VLOOKUP(B14,Пользователи!$A:$B,2,0),"нет в списке") -> A | I14: =IF(H14="нет в списке","нет пользователя",IF(H14<>C14,"группа не совпала","ок")) -> ок
A15: 5014 | B15: 1009 | C15: A | D15: 45402.847 | E15: 45402.847 | H15: =IFERROR(VLOOKUP(B15,Пользователи!$A:$B,2,0),"нет в списке") -> A | I15: =IF(H15="нет в списке","нет пользователя",IF(H15<>C15,"группа не совпала","ок")) -> ок
A16: 5015 | B16: 1010 | C16: A | D16: 45409.56 | H16: =IFERROR(VLOOKUP(B16,Пользователи!$A:$B,2,0),"нет в списке") -> A | I16: =IF(H16="нет в списке","нет пользователя",IF(H16<>C16,"группа не совпала","ок")) -> ок
A17: 5016 | B17: 1011 | C17: A | D17: 45403.85 | E17: 45403.851 | F17: 45403.853 | G17: 45403.856 | H17: =IFERROR(VLOOKUP(B17,Пользователи!$A:$B,2,0),"нет в списке") -> A | I17: =IF(H17="нет в списке","нет пользователя",IF(H17<>C17,"группа не совпала","ок")) -> ок
A18: 5017 | B18: 1011 | C18: A | D18: 45384.907 | E18: 45384.908 | F18: 45384.91 | G18: 45384.914 | H18: =IFERROR(VLOOKUP(B18,Пользователи!$A:$B,2,0),"нет в списке") -> A | I18: =IF(H18="нет в списке","нет пользователя",IF(H18<>C18,"группа не совпала","ок")) -> ок
A19: 5018 | B19: 1011 | C19: A | D19: 45398.783 | E19: 45398.783 | F19: 45398.785 | G19: 45398.79 | H19: =IFERROR(VLOOKUP(B19,Пользователи!$A:$B,2,0),"нет в списке") -> A | I19: =IF(H19="нет в списке","нет пользователя",IF(H19<>C19,"группа не совпала","ок")) -> ок
A20: 5019 | B20: 1012 | C20: A | D20: 45389.642 | E20: 45389.643 | F20: 45389.644 | G20: 45389.648 | H20: =IFERROR(VLOOKUP(B20,Пользователи!$A:$B,2,0),"нет в списке") -> A | I20: =IF(H20="нет в списке","нет пользователя",IF(H20<>C20,"группа не совпала","ок")) -> ок
A21: 5020 | B21: 1013 | C21: A | D21: 45386.893 | E21: 45386.897 | H21: =IFERROR(VLOOKUP(B21,Пользователи!$A:$B,2,0),"нет в списке") -> A | I21: =IF(H21="нет в списке","нет пользователя",IF(H21<>C21,"группа не совпала","ок")) -> ок
A22: 5021 | B22: 1013 | C22: A | D22: 45388.485 | E22: 45388.489 | H22: =IFERROR(VLOOKUP(B22,Пользователи!$A:$B,2,0),"нет в списке") -> A | I22: =IF(H22="нет в списке","нет пользователя",IF(H22<>C22,"группа не совпала","ок")) -> ок
A23: 5022 | B23: 1014 | C23: A | D23: 45394.2 | E23: 45394.201 | H23: =IFERROR(VLOOKUP(B23,Пользователи!$A:$B,2,0),"нет в списке") -> A | I23: =IF(H23="нет в списке","нет пользователя",IF(H23<>C23,"группа не совпала","ок")) -> ок
A24: 5023 | B24: 1015 | C24: A | D24: 45409.375 | E24: 45409.378 | F24: 45409.381 | G24: 45409.385 | H24: =IFERROR(VLOOKUP(B24,Пользователи!$A:$B,2,0),"нет в списке") -> A | I24: =IF(H24="нет в списке","нет пользователя",IF(H24<>C24,"группа не совпала","ок")) -> ок
A25: 5024 | B25: 1015 | C25: A | D25: 45389.731 | E25: 45389.732 | F25: 45389.735 | G25: 45389.74 | H25: =IFERROR(VLOOKUP(B25,Пользователи!$A:$B,2,0),"нет в списке") -> A | I25: =IF(H25="нет в списке","нет пользователя",IF(H25<>C25,"группа не совпала","ок")) -> ок
A26: 5025 | B26: 1015 | C26: A | D26: 45384.34 | E26: 45384.342 | F26: 45384.344 | G26: 45384.348 | H26: =IFERROR(VLOOKUP(B26,Пользователи!$A:$B,2,0),"нет в списке") -> A | I26: =IF(H26="нет в списке","нет пользователя",IF(H26<>C26,"группа не совпала","ок")) -> ок
A27: 5026 | B27: 1016 | C27: A | D27: 45391.912 | H27: =IFERROR(VLOOKUP(B27,Пользователи!$A:$B,2,0),"нет в списке") -> A | I27: =IF(H27="нет в списке","нет пользователя",IF(H27<>C27,"группа не совпала","ок")) -> ок
A28: 5027 | B28: 1017 | C28: A | D28: 45395.698 | E28: 45395.7 | F28: 45395.703 | H28: =IFERROR(VLOOKUP(B28,Пользователи!$A:$B,2,0),"нет в списке") -> A | I28: =IF(H28="нет в списке","нет пользователя",IF(H28<>C28,"группа не совпала","ок")) -> ок
A29: 5028 | B29: 1018 | C29: A | D29: 45405.001 | E29: 45405.002 | F29: 45405.007 | G29: 45405.01 | H29: =IFERROR(VLOOKUP(B29,Пользователи!$A:$B,2,0),"нет в списке") -> A | I29: =IF(H29="нет в списке","нет пользователя",IF(H29<>C29,"группа не совпала","ок")) -> ок
A30: 5029 | B30: 1018 | C30: A | D30: 45399.369 | H30: =IFERROR(VLOOKUP(B30,Пользователи!$A:$B,2,0),"нет в списке") -> A | I30: =IF(H30="нет в списке","нет пользователя",IF(H30<>C30,"группа не совпала","ок")) -> ок
A31: 5030 | B31: 1019 | C31: A | D31: 45409.024 | E31: 45409.025 | H31: =IFERROR(VLOOKUP(B31,Пользователи!$A:$B,2,0),"нет в списке") -> A | I31: =IF(H31="нет в списке","нет пользователя",IF(H31<>C31,"группа не совпала","ок")) -> ок
A32: 5031 | B32: 1019 | C32: A | D32: 45399.902 | E32: 45399.903 | H32: =IFERROR(VLOOKUP(B32,Пользователи!$A:$B,2,0),"нет в списке") -> A | I32: =IF(H32="нет в списке","нет пользователя",IF(H32<>C32,"группа не совпала","ок")) -> ок
A33: 5032 | B33: 1019 | C33: A | D33: 45412.806 | E33: 45412.808 | H33: =IFERROR(VLOOKUP(B33,Пользователи!$A:$B,2,0),"нет в списке") -> A | I33: =IF(H33="нет в списке","нет пользователя",IF(H33<>C33,"группа не совпала","ок")) -> ок
A34: 5033 | B34: 1020 | C34: A | D34: 45392.948 | E34: 45392.949 | F34: 45392.953 | G34: 45392.956 | H34: =IFERROR(VLOOKUP(B34,Пользователи!$A:$B,2,0),"нет в списке") -> A | I34: =IF(H34="нет в списке","нет пользователя",IF(H34<>C34,"группа не совпала","ок")) -> ок
A35: 5034 | B35: 1020 | C35: A | D35: 45400.963 | H35: =IFERROR(VLOOKUP(B35,Пользователи!$A:$B,2,0),"нет в списке") -> A | I35: =IF(H35="нет в списке","нет пользователя",IF(H35<>C35,"группа не совпала","ок")) -> ок
A36: 5035 | B36: 1020 | C36: A | D36: 45406.033 | E36: 45406.034 | H36: =IFERROR(VLOOKUP(B36,Пользователи!$A:$B,2,0),"нет в списке") -> A | I36: =IF(H36="нет в списке","нет пользователя",IF(H36<>C36,"группа не совпала","ок")) -> ок
A37: 5036 | B37: 1021 | C37: A | D37: 45412.97 | E37: 45412.972 | F37: 45412.976 | G37: 45412.979 | H37: =IFERROR(VLOOKUP(B37,Пользователи!$A:$B,2,0),"нет в списке") -> A | I37: =IF(H37="нет в списке","нет пользователя",IF(H37<>C37,"группа не совпала","ок")) -> ок
A38: 5037 | B38: 1021 | C38: A | D38: 45390.322 | E38: 45390.325 | F38: 45390.326 | G38: 45390.331 | H38: =IFERROR(VLOOKUP(B38,Пользователи!$A:$B,2,0),"нет в списке") -> A | I38: =IF(H38="нет в списке","нет пользователя",IF(H38<>C38,"группа не совпала","ок")) -> ок
A39: 5038 | B39: 1021 | C39: A | D39: 45394.246 | E39: 45394.248 | H39: =IFERROR(VLOOKUP(B39,Пользователи!$A:$B,2,0),"нет в списке") -> A | I39: =IF(H39="нет в списке","нет пользователя",IF(H39<>C39,"группа не совпала","ок")) -> ок
A40: 5039 | B40: 1022 | C40: A | D40: 45391.551 | E40: 45391.553 | H40: =IFERROR(VLOOKUP(B40,Пользователи!$A:$B,2,0),"нет в списке") -> A | I40: =IF(H40="нет в списке","нет пользователя",IF(H40<>C40,"группа не совпала","ок")) -> ок
...

Sheet Пользователи
A1: user_id | B1: group | C1: age | D1: city | E1: device_type
A2: 1001 | B2: A | C2: 31 | D2: Москва | E2: ios
A3: 1002 | B3: A | C3: 31 | D3: Москва | E3: ios
A4: 1003 | B4: A | C4: 25 | D4: Москва | E4: android
A5: 1004 | B5: A | C5: 20 | D5: Москва | E5: ios
A6: 1005 | B6: A | C6: 34 | D6: Москва | E6: ios
A7: 1006 | B7: A | C7: 42 | D7: Регион | E7: android
A8: 1007 | B8: A | C8: 34 | D8: Регион | E8: ios
A9: 1008 | B9: A | C9: 43 | D9: Регион | E9: ios
A10: 1009 | B10: A | C10: 30 | D10: Москва | E10: android
A11: 1010 | B11: A | C11: 26 | D11: Москва | E11: android
A12: 1011 | B12: A | C12: 45 | D12: СПб | E12: ios
A13: 1012 | B13: A | C13: 41 | D13: Регион | E13: ios
... A1501: 2500 | B1501: B | C1501: 39 | D1501: Москва | E1501: ios

Sheet Платежи
A1: payment_id | B1: user_id | C1: group | D1: step1_opened | E1: step2_entered | F1: step3_confirmed | G1: step4_success
A2: 5001 | B2: 1001 | C2: A | D2: 45398.254 | E2: 45398.257
A3: 5002 | B3: 1002 | C3: A | D3: 45394.318 | E3: 45394.32
A4: 5003 | B4: 1003 | C4: A | D4: 45408.835 | E4: 45408.838
A5: 5004 | B5: 1004 | C5: A | D5: 45391.668
A6: 5005 | B6: 1004 | C6: A | D6: 45386.157 | E6: 45386.162 | F6: 45386.165 | G6: 45386.168
A7: 5006 | B7: 1004 | C7: A | D7: 45406.726 | E7: 45406.727 | F7: 45406.729 | G7: 45406.733
A8: 5007 | B8: 1005 | C8: A | D8: 45393.882 | E8: 45393.883
A9: 5008 | B9: 1006 | C9: A | D9: 45394.575 | E9: 45394.578 | F9: 45394.58 | G9: 45394.583
A10: 5009 | B10: 1007 | C10: A | D10: 45391.478 | E10: 45391.479 | F10: 45391.483 | G10: 45391.488
A11: 5010 | B11: 1007 | C11: A | D11: 45390.287
A12: 5011 | B12: 1007 | C12: A | D12: 45405.374 | E12: 45405.374 | F12: 45405.376
A13: 5012 | B13: 1008 | C13: A | D13: 45391.378
A14: 5013 | B14: 1009 | C14: A | D14: 45406.451 | E14: 45406.454
A15: 5014 | B15: 1009 | C15: A | D15: 45402.847 | E15: 45402.847
A16: 5015 | B16: 1010 | C16: A | D16: 45409.56
A17: 5016 | B17: 1011 | C17: A | D17: 45403.85 | E17: 45403.851 | F17: 45403.853 | G17: 45403.856
A18: 5017 | B18: 1011 | C18: A | D18: 45384.907 | E18: 45384.908 | F18: 45384.91 | G18: 45384.914
A19: 5018 | B19: 1011 | C19: A | D19: 45398.783 | E19: 45398.783 | F19: 45398.785 | G19: 45398.79
A20: 5019 | B20: 1012 | C20: A | D20: 45389.642 | E20: 45389.643 | F20: 45389.644 | G20: 45389.648
A21: 5020 | B21: 1013 | C21: A | D21: 45386.893 | E21: 45386.897
A22: 5021 | B22: 1013 | C22: A | D22: 45388.485 | E22: 45388.489
A23: 5022 | B23: 1014 | C23: A | D23: 45394.2 | E23: 45394.201
A24: 5023 | B24: 1015 | C24: A | D24: 45409.375 | E24: 45409.378 | F24: 45409.381 | G24: 45409.385
A25: 5024 | B25: 1015 | C25: A | D25: 45389.731 | E25: 45389.732 | F25: 45389.735 | G25: 45389.74
A26: 5025 | B26: 1015 | C26: A | D26: 45384.34 | E26: 45384.342 | F26: 45384.344 | G26: 45384.348
A27: 5026 | B27: 1016 | C27: A | D27: 45391.912
A28: 5027 | B28: 1017 | C28: A | D28: 45395.698 | E28: 45395.7 | F28: 45395.703
A29: 5028 | B29: 1018 | C29: A | D29: 45405.001 | E29: 45405.002 | F29: 45405.007 | G29: 45405.01
A30: 5029 | B30: 1018 | C30: A | D30: 45399.369
A31: 5030 | B31: 1019 | C31: A | D31: 45409.024 | E31: 45409.025
A32: 5031 | B32: 1019 | C32: A | D32: 45399.902 | E32: 45399.903
A33: 5032 | B33: 1019 | C33: A | D33: 45412.806 | E33: 45412.808
A34: 5033 | B34: 1020 | C34: A | D34: 45392.948 | E34: 45392.949 | F34: 45392.953 | G34: 45392.956
A35: 5034 | B35: 1020 | C35: A | D35: 45400.963
A36: 5035 | B36: 1020 | C36: A | D36: 45406.033 | E36: 45406.034
A37: 5036 | B37: 1021 | C37: A | D37: 45412.97 | E37: 45412.972 | F37: 45412.976 | G37: 45412.979
A38: 5037 | B38: 1021 | C38: A | D38: 45390.322 | E38: 45390.325 | F38: 45390.326 | G38: 45390.331
A39: 5038 | B39: 1021 | C39: A | D39: 45394.246 | E39: 45394.248
A40: 5039 | B40: 1022 | C40: A | D40: 45391.551 | E40: 45391.553
...
